[2024-04-15T10:00:25.368+0000] {local_task_job_runner.py:120} INFO - ::group::Pre task execution logs
[2024-04-15T10:00:25.392+0000] {taskinstance.py:2073} INFO - Dependencies all met for dep_context=non-requeueable deps ti=<TaskInstance: test_postgres_dag.insert_to_pet_table manual__2024-04-15T10:00:21.083673+00:00 [queued]>
[2024-04-15T10:00:25.402+0000] {taskinstance.py:2073} INFO - Dependencies all met for dep_context=requeueable deps ti=<TaskInstance: test_postgres_dag.insert_to_pet_table manual__2024-04-15T10:00:21.083673+00:00 [queued]>
[2024-04-15T10:00:25.402+0000] {taskinstance.py:2303} INFO - Starting attempt 1 of 1
[2024-04-15T10:00:25.416+0000] {taskinstance.py:2327} INFO - Executing <Task(PostgresOperator): insert_to_pet_table> on 2024-04-15 10:00:21.083673+00:00
[2024-04-15T10:00:25.422+0000] {warnings.py:110} WARNING - /home/***/.local/lib/python3.12/site-packages/***/task/task_runner/standard_task_runner.py:61: DeprecationWarning: This process (pid=906) is multi-threaded, use of fork() may lead to deadlocks in the child.
  pid = os.fork()

[2024-04-15T10:00:25.424+0000] {standard_task_runner.py:63} INFO - Started process 908 to run task
[2024-04-15T10:00:25.424+0000] {standard_task_runner.py:90} INFO - Running: ['***', 'tasks', 'run', 'test_postgres_dag', 'insert_to_pet_table', 'manual__2024-04-15T10:00:21.083673+00:00', '--job-id', '64', '--raw', '--subdir', 'DAGS_FOLDER/test_postgres_dag.py', '--cfg-path', '/tmp/tmp3iqblgjx']
[2024-04-15T10:00:25.426+0000] {standard_task_runner.py:91} INFO - Job 64: Subtask insert_to_pet_table
[2024-04-15T10:00:25.470+0000] {task_command.py:426} INFO - Running <TaskInstance: test_postgres_dag.insert_to_pet_table manual__2024-04-15T10:00:21.083673+00:00 [running]> on host 6f78617af605
[2024-04-15T10:00:25.554+0000] {taskinstance.py:2644} INFO - Exporting env vars: AIRFLOW_CTX_DAG_OWNER='***' AIRFLOW_CTX_DAG_ID='test_postgres_dag' AIRFLOW_CTX_TASK_ID='insert_to_pet_table' AIRFLOW_CTX_EXECUTION_DATE='2024-04-15T10:00:21.083673+00:00' AIRFLOW_CTX_TRY_NUMBER='1' AIRFLOW_CTX_DAG_RUN_ID='manual__2024-04-15T10:00:21.083673+00:00'
[2024-04-15T10:00:25.555+0000] {taskinstance.py:430} INFO - ::endgroup::
[2024-04-15T10:00:25.567+0000] {sql.py:276} INFO - Executing: 
            INSERT INTO pet (pet_id, name, pet_type, birth_date, owner)
            VALUES (1, 'Max', 'Dog', '2018-07-05', 'Jane');
            INSERT INTO pet (pet_id, name, pet_type, birth_date, owner)
            VALUES (2, 'Susie', 'Cat', '2019-05-01', 'Phil');
            INSERT INTO pet (pet_id, name, pet_type, birth_date, owner)
            VALUES (3, 'Lester', 'Hamster', '2020-06-23', 'Lily');
            INSERT INTO pet (pet_id, name, pet_type, birth_date, owner)
            VALUES (4, 'Quincy', 'Parrot', '2013-08-11', 'Anne');
            
[2024-04-15T10:00:25.575+0000] {base.py:84} INFO - Using connection ID 'postgres_local_test' for task execution.
[2024-04-15T10:00:25.584+0000] {base.py:84} INFO - Using connection ID 'postgres_local_test' for task execution.
[2024-04-15T10:00:25.593+0000] {sql.py:457} INFO - Running statement: 
            INSERT INTO pet (pet_id, name, pet_type, birth_date, owner)
            VALUES (1, 'Max', 'Dog', '2018-07-05', 'Jane');
            INSERT INTO pet (pet_id, name, pet_type, birth_date, owner)
            VALUES (2, 'Susie', 'Cat', '2019-05-01', 'Phil');
            INSERT INTO pet (pet_id, name, pet_type, birth_date, owner)
            VALUES (3, 'Lester', 'Hamster', '2020-06-23', 'Lily');
            INSERT INTO pet (pet_id, name, pet_type, birth_date, owner)
            VALUES (4, 'Quincy', 'Parrot', '2013-08-11', 'Anne');
            , parameters: None
[2024-04-15T10:00:25.597+0000] {taskinstance.py:441} INFO - ::group::Post task execution logs
[2024-04-15T10:00:25.597+0000] {taskinstance.py:2890} ERROR - Task failed with exception
Traceback (most recent call last):
  File "/home/airflow/.local/lib/python3.12/site-packages/airflow/models/taskinstance.py", line 465, in _execute_task
    result = _execute_callable(context=context, **execute_callable_kwargs)
             ^^^^^^^^^^^^^^^^^^^^^^^^^^^^^^^^^^^^^^^^^^^^^^^^^^^^^^^^^^^^^
  File "/home/airflow/.local/lib/python3.12/site-packages/airflow/models/taskinstance.py", line 432, in _execute_callable
    return execute_callable(context=context, **execute_callable_kwargs)
           ^^^^^^^^^^^^^^^^^^^^^^^^^^^^^^^^^^^^^^^^^^^^^^^^^^^^^^^^^^^^
  File "/home/airflow/.local/lib/python3.12/site-packages/airflow/models/baseoperator.py", line 400, in wrapper
    return func(self, *args, **kwargs)
           ^^^^^^^^^^^^^^^^^^^^^^^^^^^
  File "/home/airflow/.local/lib/python3.12/site-packages/airflow/providers/common/sql/operators/sql.py", line 282, in execute
    output = hook.run(
             ^^^^^^^^^
  File "/home/airflow/.local/lib/python3.12/site-packages/airflow/providers/common/sql/hooks/sql.py", line 404, in run
    self._run_command(cur, sql_statement, parameters)
  File "/home/airflow/.local/lib/python3.12/site-packages/airflow/providers/common/sql/hooks/sql.py", line 462, in _run_command
    cur.execute(sql_statement)
psycopg2.errors.UniqueViolation: duplicate key value violates unique constraint "pet_pkey"
DETAIL:  Key (pet_id)=(1) already exists.

[2024-04-15T10:00:25.607+0000] {taskinstance.py:1205} INFO - Marking task as FAILED. dag_id=test_postgres_dag, task_id=insert_to_pet_table, execution_date=20240415T100021, start_date=20240415T100025, end_date=20240415T100025
[2024-04-15T10:00:25.619+0000] {standard_task_runner.py:110} ERROR - Failed to execute job 64 for task insert_to_pet_table (duplicate key value violates unique constraint "pet_pkey"
DETAIL:  Key (pet_id)=(1) already exists.
; 908)
[2024-04-15T10:00:25.638+0000] {local_task_job_runner.py:240} INFO - Task exited with return code 1
[2024-04-15T10:00:25.660+0000] {taskinstance.py:3482} INFO - 0 downstream tasks scheduled from follow-on schedule check
[2024-04-15T10:00:25.661+0000] {local_task_job_runner.py:222} INFO - ::endgroup::
